Workbook

Sheet RESUMEN
A1: STOCK DE ENVASES VACIOS CERES PERÚ
A2: ITEM | B2: DESCRIPCIÓN DEL ARTICULO | C2: STOCK ACTUALIZADO
A3: 1 | B3: UREA * 50 KG. | C3: ='UREA FERTI (50Kg)'!G60 -> 6487
A4: 2 | B4: FOSFATO DIAMONICO * 50 KG. | C4: ='FOSFATO DIAMONICO (50Kg)'!G33 -> 4279
A5: 3 | B5: SULFATO DE AMONIO * 50 KG. | C5: ='SULFATO DE AMONIO (50Kg) '!G29 -> 6465
A6: 4 | B6: ADITIVO MARRON - BOLSAS * 20 KG. | C6: ='ADITIVO MARRON (20Kg)'!G3 -> 3
A7: 5 | B7: NITRATO DE AMONIO * 50 KG. - POLIETILENO | C7: ='NIT. DE AMONIO (50Kg)'!G14 -> 4907
A8: 6 | B8: NITRATO DE AMONIO * 50 KG. - POLIPROPILENO | C8: ='NIT. DE AMONIO (50Kg) POLIPROPI'!G10 -> 9
A9: 7 | B9: CLORURO DE POTASIO *50 KG. | C9: 1968
A10: 8 | B10: Nitro-S Premium | C10: ='NITRO S PREMIUM(50Kg)'!G7 -> 17
A11: 9 | B11: Super Blue x50KG | C11: ='SUPER BLUE (50Kg)'!G5 -> 0
A12: 10 | B12: NPK 20-20-20 | C12: ='NPK 20-20-20'!G5 -> 1900
A13: 11 | B13: Papa Sierra | C13: ='PAPA SIERRA (50Kg)'!G4 -> 1200

Sheet UREA FERTI (50Kg)
A1: Item | B1: Descripción del artículo | C1: FECHA | D1: OPERACIÓN | E1: INGRESO | F1: SALIDA | G1: STOCK
A2: 1 | B2: UREA FERTI * 50 KG. | C2: 45279 | D2: RECEPCION - GR: 2743 | E2: 10200 | F2: 0 | G2: =E2-F2 -> 10200
A3: 1 | B3: UREA FERTI * 50 KG. | C3: 45738 | D3: RECEPCION - GR: EG07- 00003103 | E3: 4000 | F3: 0 | G3: =G2+E3-F3 -> 14200
A4: 1 | B4: UREA FERTI * 50 KG. | C4: * | D4: TOTAL ENSAQUE | E4: 0 | F4: 12502 | G4: =G3+E4-F4 -> 1698
A5: 1 | B5: UREA FERTI * 50 KG. | C5: * | D5: TOTAL MANIPULEO / DESPACHO | E5: 0 | F5: 345 | G5: =G4+E5-F5 -> 1353
A6: 1 | B6: UREA FERTI * 50 KG. | C6: * | D6: ENSAQUE - SACOS EXCEDENTES | E6: 0 | F6: 20 | G6: =G5+E6-F6 -> 1333
A7: 1 | B7: UREA FERTI * 50 KG. | C7: * | D7: FALTANTE RECEPCION - 1° LOTE | E7: 0 | F7: 20 | G7: =G6+E7-F7 -> 1313
A8: 1 | B8: UREA FERTI * 50 KG. | C8: 45807 | D8: RECEPCION - GR: EG07- 00012700 | E8: 2000 | F8: 0 | G8: =G7+E8-F8 -> 3313
A9: 1 | B9: UREA FERTI * 50 KG. | C9: 45824 | D9: ENSAQUE PEDIDO 100 TN. - UREA GRANULADA | E9: 0 | F9: 1584 | G9: =G8+E9-F9 -> 1729
A10: 1 | B10: UREA FERTI * 50 KG. | C10: 45825 | D10: ENSAQUE PEDIDO 100 TN. - UREA GRANULADA | E10: 0 | F10: 418 | G10: =G9+E10-F10 -> 1311
A11: 1 | B11: UREA FERTI * 50 KG. | C11: 45834 | D11: RECEPCION - GR: EG07- 00013488 | E11: 2000 | F11: 0 | G11: =G10+E11-F11 -> 3311
A12: 1 | B12: UREA FERTI * 50 KG. | C12: 45850 | D12: ENSAQUE PEDIDO TOTAL - UREA GRANULADA | E12: 0 | F12: 3187 | G12: =G11+E12-F12 -> 124
A13: 1 | B13: UREA FERTI * 50 KG. | C13: 45869 | D13: RECEPCION - GR: EG07- 00014172 | E13: 5000 | F13: 0 | G13: =G12+E13-F13 -> 5124
A14: 1 | B14: UREA FERTI * 50 KG. | C14: 45870 | D14: ENSAQUE PEDIDO TOTAL - UREA GRANULADA | E14: 0 | F14: 423 | G14: =G13+E14-F14 -> 4701
A15: 1 | B15: UREA FERTI * 50 KG. | C15: 45874 | D15: MANIPULEO - DESPACHO | E15: 0 | F15: 3 | G15: =G14+E15-F15 -> 4698
A16: 1 | B16: UREA FERTI * 50 KG. | C16: 45876 | D16: ENSAQUE PEDIDO 150 TN. - UREA PERLADA | E16: 0 | F16: 3007 | G16: =G15+E16-F16 -> 1691
A17: 1 | B17: UREA FERTI * 50 KG. | C17: 45882 | D17: MANIPULEO - DESPACHO | E17: 0 | F17: 2 | G17: =G16+E17-F17 -> 1689
A18: 1 | B18: UREA FERTI * 50 KG. | C18: 45894 | D18: MANIPULEO - DESPACHO | E18: 0 | F18: 38 | G18: =G17+E18-F18 -> 1651
A19: 1 | B19: UREA FERTI * 50 KG. | C19: 45895 | D19: MANIPULEO - DESPACHO | E19: 0 | F19: 7 | G19: =G18+E19-F19 -> 1644
... A34: 1 | B34: UREA FERTI * 50 KG. | C34: 45980 | D34: RECEPCION - GR: EG07- 00018086 | E34: 6000 | F34: 0 | G34: =G33+E34-F34 -> 8513
A35: 1 | B35: UREA FERTI * 50 KG. | C35: 45983 | D35: ENSAQUE 100 TM - UREA GRANULADA | F35: 2010 | G35: =G34+E35-F35 -> 6503
A36: 1 | B36: UREA FERTI * 50 KG. | C36: 45987 | D36: MANIPULEO - DESPACHO | E36: 0 | F36: 14 | G36: =G35+E36-F36 -> 6489
A37: 1 | B37: UREA FERTI * 50 KG. | C37: 45988 | D37: MANIPULEO - DESPACHO | E37: 0 | F37: 5 | G37: =G36+E37-F37 -> 6484
A38: 1 | B38: UREA FERTI * 50 KG. | C38: 45989 | D38: ENSAQUE 200 TM - UREA GRANULADA | F38: 3516 | G38: =G37+E38-F38 -> 2968
A39: 1 | B39: UREA FERTI * 50 KG. | C39: 45992 | D39: MANIPULEO - DESPACHO | F39: 3 | G39: =G38+E39-F39 -> 2965
A40: 1 | B40: UREA FERTI * 50 KG. | C40: 45992 | D40: MANIPULEO - DESPACHO | F40: 4 | G40: =G39+E40-F40 -> 2961
A41: 1 | B41: UREA FERTI * 50 KG. | C41: 45994 | D41: MANIPULEO - DESPACHO | F41: 4 | G41: =G40+E41-F41 -> 2957
A42: 1 | B42: UREA FERTI * 50 KG. | C42: 45995 | D42: MANIPULEO - DESPACHO | F42: 15 | G42: =G41+E42-F42 -> 2942
A43: 1 | B43: UREA FERTI * 50 KG. | C43: 45997 | D43: MANIPULEO - DESPACHO | F43: 19 | G43: =G42+E43-F43 -> 2923
A44: 1 | B44: UREA FERTI * 50 KG. | C44: 46001 | D44: MANIPULEO - DESPACHO | F44: 10 | G44: =G43+E44-F44 -> 2913
A45: 1 | B45: UREA FERTI * 50 KG. | C45: 46002 | D45: ENSAQUE 100 TM - UREA PERLADA | F45: 2024 | G45: =G44+E45-F45 -> 889
A46: 1 | B46: UREA FERTI * 50 KG. | C46: 46002 | D46: ENSAQUE 42 TM - UREA PERLADA | F46: 840 | G46: =G45+E46-F46 -> 49
A47: 1 | B47: UREA FERTI * 50 KG. | C47: 46009 | D47: RECEPCION - GR: EG07- 00018680 | E47: 6000 | F47: 0 | G47: =G46+E47-F47 -> 6049
A48: 1 | B48: UREA FERTI * 50 KG. | C48: 46021 | D48: RECEPCION - GR: EG07- 00019037 | E48: 6000 | F48: 0 | G48: =G47+E48-F48 -> 12049
A49: 1 | B49: UREA FERTI * 50 KG. | C49: 46003 | D49: ENSAQUE 46.5 TM - UREA PERLADA | F49: 927 | G49: =G48+E49-F49 -> 11122
A50: 1 | B50: UREA FERTI * 50 KG. | C50: 46003 | D50: ENSAQUE 100 TM - UREA PERLADA | F50: 0 | G50: =G49+E50-F50 -> 11122
A51: 1 | B51: UREA FERTI * 50 KG. | C51: 46006 | D51: ENSAQUE 150 TM - UREA PERLADA | F51: 3014 | G51: =G50+E51-F51 -> 8108
A52: 1 | B52: UREA FERTI * 50 KG. | C52: 22/12-03/01 | D52: ENSAQUE 125.4 TM - UREA GRANULADA | F52: 2512 | G52: =G51+E52-F52 -> 5596
A53: 1 | B53: UREA FERTI * 50 KG. | C53: 15/12/2025-03/01 | D53: ENSAQUE 50 TM - UREA PERLADA | F53: 1010 | G53: =G52+E53-F53 -> 4586
A54: 1 | B54: UREA FERTI * 50 KG. | C54: 46029 | D54: MANIPULEO - DESPACHO | F54: 16 | G54: =G53+E54-F54 -> 4570
...

Sheet FOSFATO DIAMONICO (50Kg)
A2: Item | B2: Descripción del artículo | C2: FECHA | D2: OPERACIÓN | E2: INGRESO | F2: SALIDA | G2: STOCK
A3: 2 | B3: FOSFATO DIAMONICO FERTI * 50 KG. | C3: 45790 | D3: RECEPCION - GR: EG07- 00012605 | E3: 5006 | F3: 0 | G3: =E3-F3 -> 5006
A4: 2 | B4: FOSFATO DIAMONICO FERTI * 50 KG. | C4: 45792 | D4: ENSAQUE PEDIDO 250 TN. | E4: 0 | F4: 4668 | G4: =E4+G3-F4 -> 338
A5: 2 | B5: FOSFATO DIAMONICO FERTI * 50 KG. | C5: 45794 | D5: ENSAQUE PEDIDO 250 TN. | E5: 0 | F5: 334 | G5: =E5+G4-F5 -> 4
A6: 2 | B6: FOSFATO DIAMONICO FERTI * 50 KG. | C6: 45813 | D6: MANIPULEO - DESPACHO | E6: 0 | F6: 2 | G6: =E6+G5-F6 -> 2
A7: 2 | B7: FOSFATO DIAMONICO FERTI * 50 KG. | C7: 45832 | D7: MANIPULEO - DESPACHO | E7: 0 | F7: 2 | G7: =E7+G6-F7 -> 0
A8: 2 | B8: FOSFATO DIAMONICO FERTI * 50 KG. | C8: 45834 | D8: RECEPCION - GR: EG07- 00013488 | E8: 5005 | F8: 0 | G8: =E8+G7-F8 -> 5005
A9: 2 | B9: FOSFATO DIAMONICO FERTI * 50 KG. | C9: 45848 | D9: ENSAQUE PEDIDO 200 TN. | E9: 0 | F9: 4003 | G9: =E9+G8-F9 -> 1002
A10: 2 | B10: FOSFATO DIAMONICO FERTI * 50 KG. | C10: 45852 | D10: MANIPULEO - DESPACHO | E10: 0 | F10: 5 | G10: =E10+G9-F10 -> 997
A11: 2 | B11: FOSFATO DIAMONICO FERTI * 50 KG. | C11: 45856 | D11: MANIPULEO - DESPACHO | E11: 0 | F11: 4 | G11: =E11+G10-F11 -> 993
A12: 2 | B12: FOSFATO DIAMONICO FERTI * 50 KG. | C12: 45859 | D12: MANIPULEO - DESPACHO | E12: 0 | F12: 4 | G12: =E12+G11-F12 -> 989
A13: 2 | B13: FOSFATO DIAMONICO FERTI * 50 KG. | C13: 45870 | D13: ENSAQUE PEDIDO TOTAL. | E13: 0 | F13: 989 | G13: =E13+G12-F13 -> 0
A14: 2 | B14: FOSFATO DIAMONICO FERTI * 50 KG. | C14: 45878 | D14: RECEPCION - GR: EG07- 00014959 | E14: 1000 | F14: 0 | G14: =E14+G13-F14 -> 1000
A15: 2 | B15: FOSFATO DIAMONICO FERTI * 50 KG. | C15: 45881 | D15: ENSAQUE PEDIDO TOTAL. | E15: 0 | F15: 984 | G15: =E15+G14-F15 -> 16
... A24: 2 | B24: FOSFATO DIAMONICO FERTI * 50 KG. | C24: 45980 | D24: RECEPCION - GR: EG07- 00018086 | E24: 4000 | F24: 0 | G24: =E24+G23-F24 -> 6451
A25: 2 | B25: FOSFATO DIAMONICO FERTI * 50 KG. | C25: 46001 | D25: MANIPULEO - DESPACHO | F25: 8 | G25: =E25+G24-F25 -> 6443
A26: 2 | B26: FOSFATO DIAMONICO FERTI * 50 KG. | C26: 46002 | D26: ENSAQUE PEDIDO 100 TN. | E26: 0 | F26: 2025 | G26: =E26+G25-F26 -> 4418
A27: 2 | B27: FOSFATO DIAMONICO FERTI * 50 KG. | C27: 46043 | D27: ENSAQUE PEDIDO 200 TN. | E27: 0 | F27: 4054 | G27: =E27+G26-F27 -> 364
A28: 2 | B28: FOSFATO DIAMONICO FERTI * 50 KG. | C28: 46039 | D28: MANIPULEO - DESPACHO | E28: 0 | F28: 19 | G28: =E28+G27-F28 -> 345
A29: 2 | B29: FOSFATO DIAMONICO FERTI * 50 KG. | C29: 46042 | D29: RECEPCION - GR: EG07- 00019333 | E29: 4000 | F29: 0 | G29: =E29+G28-F29 -> 4345
A30: 2 | B30: FOSFATO DIAMONICO FERTI * 50 KG. | C30: 46044 | D30: MANIPULEO - DESPACHO | E30: 0 | F30: 20 | G30: =E30+G29-F30 -> 4325
A31: 2 | B31: FOSFATO DIAMONICO FERTI * 50 KG. | C31: 46045 | D31: MANIPULEO - DESPACHO | E31: 0 | F31: 15 | G31: =E31+G30-F31 -> 4310
A32: 2 | B32: FOSFATO DIAMONICO FERTI * 50 KG. | C32: 46049 | D32: MANIPULEO - DESPACHO | E32: 0 | F32: 22 | G32: =E32+G31-F32 -> 4288
A33: 2 | B33: FOSFATO DIAMONICO FERTI * 50 KG. | C33: 46049 | D33: ROTO EN RUMA | E33: 0 | F33: 9 | G33: =E33+G32-F33 -> 4279

Sheet SULFATO DE AMONIO (50Kg) 
A3: Item | B3: Descripción del artículo | C3: FECHA | D3: OPERACIÓN | E3: INGRESO | F3: SALIDA | G3: STOCK
A4: 3 | B4: SULFATO DE AMONIO FERTI * 50 KG. | C4: 45790 | D4: RECEPCION - GR: EG07- 00012605 | E4: 3000 | F4: 0 | G4: =E4-F4 -> 3000
A5: 3 | B5: SULFATO DE AMONIO FERTI * 50 KG. | C5: 45881 | D5: ENSAQUE PEDIDO 20 TN. | E5: 0 | F5: 405 | G5: =G4+E5-F5 -> 2595
A6: 3 | B6: SULFATO DE AMONIO FERTI * 50 KG. | C6: 45884 | D6: ENSAQUE PEDIDO 100 TN. | E6: 0 | F6: 1745 | G6: =G5+E6-F6 -> 850
A7: 3 | B7: SULFATO DE AMONIO FERTI * 50 KG. | C7: 45885 | D7: ENSAQUE PEDIDO 100 TN. | E7: 0 | F7: 277 | G7: =G6+E7-F7 -> 573
A8: 3 | B8: SULFATO DE AMONIO FERTI * 50 KG. | C8: 45894 | D8: MANIPULEO - DESPACHO | E8: 0 | F8: 4 | G8: =G7+E8-F8 -> 569
A9: 3 | B9: SULFATO DE AMONIO FERTI * 50 KG. | C9: 45895 | D9: MANIPULEO - DESPACHO | E9: 0 | F9: 16 | G9: =G8+E9-F9 -> 553
A10: 3 | B10: SULFATO DE AMONIO FERTI * 50 KG. | C10: 45897 | D10: MANIPULEO - DESPACHO | E10: 0 | F10: 1 | G10: =G9+E10-F10 -> 552
A11: 3 | B11: SULFATO DE AMONIO FERTI * 50 KG. | C11: 45904 | D11: MANIPULEO - DESPACHO | E11: 0 | F11: 9 | G11: =G10+E11-F11 -> 543
A12: 3 | B12: SULFATO DE AMONIO FERTI * 50 KG. | C12: 45906 | D12: MANIPULEO - DESPACHO | E12: 0 | F12: 4 | G12: =G11+E12-F12 -> 539
A13: 3 | B13: SULFATO DE AMONIO FERTI * 50 KG. | C13: 45906 | D13: RECEPCION - GR: EG07- 00016079 | E13: 3000 | F13: 0 | G13: =G12+E13-F13 -> 3539
A14: 3 | B14: SULFATO DE AMONIO FERTI * 50 KG. | C14: 45909 | D14: ENSAQUE PEDIDO TOTAL | E14: 0 | F14: 3534 | G14: =G13+E14-F14 -> 5
A15: 3 | B15: SULFATO DE AMONIO FERTI * 50 KG. | C15: 45911 | D15: MANIPULEO - DESPACHO | E15: 0 | F15: 5 | G15: =G14+E15-F15 -> 0
A16: 3 | B16: SULFATO DE AMONIO FERTI * 50 KG. | C16: 45947 | D16: RECEPCION - GR: EG07- 00017334 / T001-00004372 | E16: 4008 | F16: 0 | G16: =G15+E16-F16 -> 4008
... A19: 3 | B19: SULFATO DE AMONIO FERTI * 50 KG. | C19: 45983 | D19: ENSAQUE PEDIDO 200 TN. | E19: 0 | F19: 4010 | G19: =G18+E19-F19 -> 3968
A20: 3 | B20: SULFATO DE AMONIO FERTI * 50 KG. | C20: 45995 | D20: MANIPULEO - DESPACHO | F20: 6 | G20: =G19+E20-F20 -> 3962
A21: 3 | B21: SULFATO DE AMONIO FERTI * 50 KG. | C21: 45997 | D21: MANIPULEO - DESPACHO | F21: 1 | G21: =G20+E21-F21 -> 3961
A22: 3 | B22: SULFATO DE AMONIO FERTI * 50 KG. | C22: 46001 | D22: MANIPULEO - DESPACHO | F22: 11 | G22: =G21+E22-F22 -> 3950
A23: 3 | B23: SULFATO DE AMONIO FERTI * 50 KG. | C23: 46003 | D23: ENSAQUE PEDIDO 90 TN. | F23: 1813 | G23: =G22+E23-F23 -> 2137
A24: 3 | B24: SULFATO DE AMONIO FERTI * 50 KG. | C24: 46009 | D24: RECEPCION - GR: EG07- 00018680 | E24: 3000 | F24: 0 | G24: =G23+E24-F24 -> 5137
A25: 3 | B25: SULFATO DE AMONIO FERTI * 50 KG. | C25: 46027 | D25: MANIPULEO - DESPACHO | F25: 2 | G25: =G24+E25-F25 -> 5135
A26: 3 | B26: SULFATO DE AMONIO FERTI * 50 KG. | C26: 46032 | D26: MANIPULEO - DESPACHO | F26: 3 | G26: =G25+E26-F26 -> 5132
A27: 3 | B27: SULFATO DE AMONIO FERTI * 50 KG. | C27: 46037 | D27: MANIPULEO - DESPACHO | F27: 5 | G27: =G26+E27-F27 -> 5127
A28: 3 | B28: SULFATO DE AMONIO FERTI * 50 KG. | C28: 46042 | D28: RECEPCION - GR: EG07- 00019333 | E28: 2000 | F28: 0 | G28: =G27+E28-F28 -> 7127
A29: 3 | B29: SULFATO DE AMONIO FERTI * 50 KG. | C29: 46046 | D29: ENSAQUE PEDIDO 90 TN. | F29: 662 | G29: =G28+E29-F29 -> 6465

Sheet ADITIVO MARRON (20Kg)
A2: Item | B2: Descripción del artículo | C2: FECHA | D2: OPERACIÓN | E2: INGRESO | F2: SALIDA | G2: STOCK
A3: 4 | B3: ADITIVO MARRON - BOLSAS * 20 KG. | C3: 45834 | D3: RECEPCION - GR: EG07- 00013488 | E3: 3 | F3: 0 | G3: =E3-F3 -> 3

Sheet NIT. DE AMONIO (50Kg)
A2: Item | B2: Descripción del artículo | C2: FECHA | D2: OPERACIÓN | E2: INGRESO | F2: SALIDA | G2: STOCK
A3: 5 | B3: NITRATO DE AMONIO * 50 KG. | C3: 45869 | D3: RECEPCION - GR: EG07- 00014172 | E3: 8000 | F3: 0 | G3: =E3-F3 -> 8000
A4: 5 | B4: NITRATO DE AMONIO * 50 KG. | C4: 45891 | D4: ENSAQUE PEDIDO 150 TN. | E4: 0 | F4: 357 | G4: =E4+G3-F4 -> 7643
A5: 5 | B5: NITRATO DE AMONIO * 50 KG. | C5: 45892 | D5: ENSAQUE PEDIDO 150 TN. | E5: 0 | F5: 814 | G5: =E5+G4-F5 -> 6829
A6: 5 | B6: NITRATO DE AMONIO * 50 KG. | C6: 45894 | D6: MANIPULEO - DESPACHO | E6: 0 | F6: 1 | G6: =E6+G5-F6 -> 6828
A7: 5 | B7: NITRATO DE AMONIO * 50 KG. | C7: 45895 | D7: MANIPULEO - DESPACHO | E7: 0 | F7: 3 | G7: =E7+G6-F7 -> 6825
A8: 5 | B8: NITRATO DE AMONIO * 50 KG. | C8: 45897 | D8: MANIPULEO - DESPACHO | E8: 0 | F8: 7 | G8: =E8+G7-F8 -> 6818
A9: 5 | B9: NITRATO DE AMONIO * 50 KG. | C9: 45902 | D9: ENSAQUE PEDIDO 150 TN. | E9: 0 | F9: 1847 | G9: =E9+G8-F9 -> 4971
A10: 5 | B10: NITRATO DE AMONIO * 50 KG. | C10: 45917 | D10: MANIPULEO - DESPACHO | E10: 0 | F10: 2 | G10: =E10+G9-F10 -> 4969
A11: 5 | B11: NITRATO DE AMONIO * 50 KG. | C11: 45918 | D11: MANIPULEO - DESPACHO | E11: 0 | F11: 16 | G11: =E11+G10-F11 -> 4953
A12: 5 | B12: NITRATO DE AMONIO * 50 KG. | C12: 45925 | D12: MANIPULEO - DESPACHO | E12: 0 | F12: 12 | G12: =E12+G11-F12 -> 4941
A13: 5 | B13: NITRATO DE AMONIO * 50 KG. | C13: 45972 | D13: MANIPULEO - DESPACHO | E13: 0 | F13: 10 | G13: =E13+G12-F13 -> 4931
A14: 5 | B14: NITRATO DE AMONIO * 50 KG. | C14: 46024 | D14: ROTO EN RUMA | E14: 0 | F14: 24 | G14: =E14+G13-F14 -> 4907

Sheet NIT. DE AMONIO (50Kg) POLIPROPI
A3: Item | B3: Descripción del artículo | C3: FECHA | D3: OPERACIÓN | E3: INGRESO | F3: SALIDA | G3: STOCK
A4: 6 | B4: NITRATO DE AMONIO * 50 KG. - POLIPROPILENO | C4: 45947 | D4: RECEPCION - GR: EG07- 00017334 | E4: 6005 | F4: 0 | G4: =+E4-F4 -> 6005
A5: 6 | B5: NITRATO DE AMONIO * 50 KG. - POLIPROPILENO | C5: 45954 | D5: ENSAQUE PEDIDO 300 TN. | E5: 0 | F5: 6003 | G5: =+E5+G4-F5 -> 2
A6: 6 | B6: NITRATO DE AMONIO * 50 KG. - POLIPROPILENO | C6: 45972 | D6: MANIPULEO - DESPACHO | E6: 0 | F6: 1 | G6: =+E6+G5-F6 -> 1
A7: 6 | B7: NITRATO DE AMONIO * 50 KG. - POLIPROPILENO | C7: 45987 | D7: MANIPULEO - DESPACHO | E7: 0 | F7: 1 | G7: =+E7+G6-F7 -> 0
A8: 6 | B8: NITRATO DE AMONIO * 50 KG. - POLIPROPILENO | C8: 46009 | D8: RECEPCION - GR: EG07- 00018680 | E8: 2011 | F8: 0 | G8: =+E8+G7-F8 -> 2011
A9: 6 | B9: NITRATO DE AMONIO * 50 KG. - POLIPROPILENO | C9: 46029 | D9: MANIPULEO - DESPACHO | E9: 0 | F9: 2 | G9: =+E9+G8-F9 -> 2009
A10: 6 | B10: NITRATO DE AMONIO * 50 KG. - POLIPROPILENO | C10: 45954 | D10: ENSAQUE PEDIDO 100 TN. | E10: 0 | F10: 2000 | G10: =+E10+G9-F10 -> 9

Sheet CLORURO DE POTASIO(50Kg)
A3: Item | B3: Descripción del artículo | C3: FECHA | D3: OPERACIÓN | E3: INGRESO | F3: SALIDA | G3: STOCK
A4: 7 | B4: CLORURO DE POTASIO *50 KG. | C4: 45980 | D4: RECEPCION - GR: EG07- 00018086 | E4: 4000 | F4: 0 | G4: =E4 -> 4000
A5: 7 | B5: CLORURO DE POTASIO *50 KG. | C5: 46377 | D5: ENSAQUE PEDIDO 100 TN. | E5: 0 | F5: 2217 | G5: =G4+E5-F5 -> 1783

Sheet NITRO S PREMIUM(50Kg)
A3: Item | B3: Descripción del artículo | C3: FECHA | D3: OPERACIÓN | E3: INGRESO | F3: SALIDA | G3: STOCK
A4: 8 | B4: NITRO S PREMIUM AMARILLO * 50 KG | C4: 45996 | D4: RECEPCION - GR: EG07- 00018460 | E4: 1200 | F4: 0 | G4: =+E4-F4 -> 1200
A5: 8 | B5: NITRO S PREMIUM AMARILLO * 50 KG | C5: 46031 | D5: ENSAQUE | E5: 0 | F5: 1203 | G5: =+G4+E5-F5 -> -3
A6: 8 | B6: NITRO S PREMIUM AMARILLO * 50 KG | C6: 46042 | D6: RECEPCION - GR: EG07- 00018333 | E6: 100 | F6: 0 | G6: =+G5+E6-F6 -> 97
A7: 8 | B7: NITRO S PREMIUM AMARILLO * 50 KG | C7: 46046 | D7: ENSAQUE | E7: 0 | F7: 80 | G7: =+G6+E7-F7 -> 17

Sheet SUPER BLUE (50Kg)
A3: Item | B3: Descripción del artículo | C3: FECHA | D3: OPERACIÓN | E3: INGRESO | F3: SALIDA | G3: STOCK
A4: 9 | B4: SUPER BLUE * 50 KG | C4: 45996 | D4: RECEPCION - GR: EG07- 00018399 | E4: 1200 | F4: 0 | G4: =+E4-F4 -> 1200
A5: 9 | B5: SUPER BLUE * 50 KG | C5: 46031 | D5: ENSAQUE | E5: 0 | F5: 1200 | G5: =+G4+E5-F5 -> 0

Sheet NPK 20-20-20
A3: Item | B3: Descripción del artículo | C3: FECHA | D3: OPERACIÓN | E3: INGRESO | F3: SALIDA | G3: STOCK
A4: 10 | B4: NPK 20-20-20 * 50 KG | C4: 46009 | D4: RECEPCION - GR: T001-00004530 | E4: 1800 | F4: 0 | G4: =+E4-F4 -> 1800
A5: 10 | B5: NPK 20-20-20 * 50 KG | C5: 46042 | D5: RECEPCION - GR: EG07- 00018333 | E5: 100 | F5: 0 | G5: =+E5+G4-F5 -> 1900

Sheet PAPA SIERRA (50Kg)
A3: Item | B3: Descripción del artículo | C3: FECHA | D3: OPERACIÓN | E3: INGRESO | F3: SALIDA | G3: STOCK
A4: 11 | B4: NITRO S PREMIUM AMARILLO * 50 KG | C4: 45996 | D4: RECEPCION - GR: EG07- 00018460 | E4: 1200 | F4: 0 | G4: =+E4-F4 -> 1200
